Workbook

Sheet Keyword Map
A1: # | B1: Keyword | C1: Primary URL | D1: Page Title | E1: Cluster Section | F1: Page Status | G1: Secondary / Supporting URL
A2: 1 | B2: tetraodontidae | C2: https://www.fishcareai.com/guides/puffer-fish-care/ | D2: Puffer Fish Care Guide: Tank, Water, Food and Species | E2: Pillar | F2: NEW | G2: https://www.fishcareai.com/guides/puffer-fish-care/types/
A3: 2 | B3: tetraodontidae fish | C3: https://www.fishcareai.com/guides/puffer-fish-care/ | D3: Puffer Fish Care Guide: Tank, Water, Food and Species | E3: Pillar | F3: NEW | G3: https://www.fishcareai.com/guides/puffer-fish-care/types/
A4: 3 | B4: tetraodontidae pufferfish | C4: https://www.fishcareai.com/guides/puffer-fish-care/ | D4: Puffer Fish Care Guide: Tank, Water, Food and Species | E4: Pillar | F4: NEW | G4: https://www.fishcareai.com/guides/puffer-fish-care/types/
A5: 4 | B5: puffer fish | C5: https://www.fishcareai.com/guides/puffer-fish-care/ | D5: Puffer Fish Care Guide: Tank, Water, Food and Species | E5: Pillar | F5: NEW
A6: 5 | B6: pufferfish | C6: https://www.fishcareai.com/guides/puffer-fish-care/ | D6: Puffer Fish Care Guide: Tank, Water, Food and Species | E6: Pillar | F6: NEW
A7: 6 | B7: puffer fish care | C7: https://www.fishcareai.com/guides/puffer-fish-care/ | D7: Puffer Fish Care Guide: Tank, Water, Food and Species | E7: Pillar | F7: NEW
A8: 7 | B8: pufferfish care | C8: https://www.fishcareai.com/guides/puffer-fish-care/ | D8: Puffer Fish Care Guide: Tank, Water, Food and Species | E8: Pillar | F8: NEW
A9: 8 | B9: how to care for puffer fish | C9: https://www.fishcareai.com/guides/puffer-fish-care/ | D9: Puffer Fish Care Guide: Tank, Water, Food and Species | E9: Pillar | F9: NEW | G9: https://www.fishcareai.com/guides/puffer-fish-care/tank-size/
A10: 9 | B10: types of puffer fish | C10: https://www.fishcareai.com/guides/puffer-fish-care/types/ | D10: Types of Puffer Fish: 20 Species by Size and Water Type | E10: Types & Species | F10: NEW | G10: https://www.fishcareai.com/guides/puffer-fish-care/
A11: 10 | B11: puffer fish species | C11: https://www.fishcareai.com/guides/puffer-fish-care/types/ | D11: Types of Puffer Fish: 20 Species by Size and Water Type | E11: Types & Species | F11: NEW | G11: https://www.fishcareai.com/guides/puffer-fish-care/
A12: 11 | B12: pufferfish species | C12: https://www.fishcareai.com/guides/puffer-fish-care/types/ | D12: Types of Puffer Fish: 20 Species by Size and Water Type | E12: Types & Species | F12: NEW | G12: https://www.fishcareai.com/guides/puffer-fish-care/
A13: 12 | B13: types of freshwater puffer fish | C13: https://www.fishcareai.com/guides/puffer-fish-care/types/ | D13: Types of Puffer Fish: 20 Species by Size and Water Type | E13: Types & Species | F13: NEW | G13: https://www.fishcareai.com/guides/puffer-fish-care/freshwater/
A14: 13 | B14: freshwater puffer fish species | C14: https://www.fishcareai.com/guides/puffer-fish-care/types/ | D14: Types of Puffer Fish: 20 Species by Size and Water Type | E14: Types & Species | F14: NEW | G14: https://www.fishcareai.com/guides/puffer-fish-care/freshwater/
A15: 14 | B15: small puffer fish | C15: https://www.fishcareai.com/guides/puffer-fish-care/types/ | D15: Types of Puffer Fish: 20 Species by Size and Water Type | E15: Types & Species | F15: NEW | G15: https://www.fishcareai.com/guides/puffer-fish-care/pea-puffer/
A16: 15 | B16: congo puffer | C16: https://www.fishcareai.com/guides/puffer-fish-care/types/ | D16: Types of Puffer Fish: 20 Species by Size and Water Type | E16: Types & Species | F16: NEW | G16: https://www.fishcareai.com/guides/puffer-fish-care/freshwater/
A17: 16 | B17: congo puffer fish | C17: https://www.fishcareai.com/guides/puffer-fish-care/types/ | D17: Types of Puffer Fish: 20 Species by Size and Water Type | E17: Types & Species | F17: NEW | G17: https://www.fishcareai.com/guides/puffer-fish-care/freshwater/
A18: 17 | B18: congo puffer care | C18: https://www.fishcareai.com/guides/puffer-fish-care/types/ | D18: Types of Puffer Fish: 20 Species by Size and Water Type | E18: Types & Species | F18: NEW | G18: https://www.fishcareai.com/guides/puffer-fish-care/freshwater/
A19: 18 | B19: avocado puffer | C19: https://www.fishcareai.com/guides/puffer-fish-care/types/ | D19: Types of Puffer Fish: 20 Species by Size and Water Type | E19: Types & Species | F19: NEW | G19: https://www.fishcareai.com/guides/puffer-fish-care/freshwater/
A20: 19 | B20: red eye puffer | C20: https://www.fishcareai.com/guides/puffer-fish-care/types/ | D20: Types of Puffer Fish: 20 Species by Size and Water Type | E20: Types & Species | F20: NEW | G20: https://www.fishcareai.com/guides/puffer-fish-care/freshwater/
... A33: 32 | B33: freshwater puffer fish tank | C33: https://www.fishcareai.com/guides/puffer-fish-care/tank-size/ | D33: Puffer Fish Tank Size: Minimum Gallons by Species | E33: Tank Size | F33: NEW | G33: https://www.fishcareai.com/guides/puffer-fish-care/freshwater/
A34: 33 | B34: puffer fish water temperature | C34: https://www.fishcareai.com/guides/puffer-fish-care/water-parameters/ | D34: Puffer Fish Water Parameters: Temperature, pH and Salinity | E34: Water Parameters | F34: NEW
A35: 34 | B35: puffer fish temperature | C35: https://www.fishcareai.com/guides/puffer-fish-care/water-parameters/ | D35: Puffer Fish Water Parameters: Temperature, pH and Salinity | E35: Water Parameters | F35: NEW
A36: 35 | B36: puffer fish water parameters | C36: https://www.fishcareai.com/guides/puffer-fish-care/water-parameters/ | D36: Puffer Fish Water Parameters: Temperature, pH and Salinity | E36: Water Parameters | F36: NEW
A37: 36 | B37: puffer fish pH | C37: https://www.fishcareai.com/guides/puffer-fish-care/water-parameters/ | D37: Puffer Fish Water Parameters: Temperature, pH and Salinity | E37: Water Parameters | F37: NEW
A38: 37 | B38: freshwater puffer water parameters | C38: https://www.fishcareai.com/guides/puffer-fish-care/water-parameters/ | D38: Puffer Fish Water Parameters: Temperature, pH and Salinity | E38: Water Parameters | F38: NEW | G38: https://www.fishcareai.com/guides/puffer-fish-care/freshwater/
A39: 38 | B39: puffer fish food | C39: https://www.fishcareai.com/guides/puffer-fish-care/food/ | D39: What Do Puffer Fish Eat? Food and Feeding Guide | E39: Food & Feeding | F39: NEW
A40: 39 | B40: what do puffer fish eat | C40: https://www.fishcareai.com/guides/puffer-fish-care/food/ | D40: What Do Puffer Fish Eat? Food and Feeding Guide | E40: Food & Feeding | F40: NEW
A41: 40 | B41: what to feed puffer fish | C41: https://www.fishcareai.com/guides/puffer-fish-care/food/ | D41: What Do Puffer Fish Eat? Food and Feeding Guide | E41: Food & Feeding | F41: NEW
A42: 41 | B42: best food for puffer fish | C42: https://www.fishcareai.com/guides/puffer-fish-care/food/ | D42: What Do Puffer Fish Eat? Food and Feeding Guide | E42: Food & Feeding | F42: NEW
A43: 42 | B43: puffer fish feeding | C43: https://www.fishcareai.com/guides/puffer-fish-care/food/ | D43: What Do Puffer Fish Eat? Food and Feeding Guide | E43: Food & Feeding | F43: NEW
A44: 43 | B44: how often to feed puffer fish | C44: https://www.fishcareai.com/guides/puffer-fish-care/food/ | D44: What Do Puffer Fish Eat? Food and Feeding Guide | E44: Food & Feeding | F44: NEW
A45: 44 | B45: puffer fish teeth | C45: https://www.fishcareai.com/guides/puffer-fish-care/teeth/ | D45: Puffer Fish Teeth: Overgrowth, Diet and Trimming | E45: Teeth | F45: NEW
A46: 45 | B46: puffer fish teeth trimming | C46: https://www.fishcareai.com/guides/puffer-fish-care/teeth/ | D46: Puffer Fish Teeth: Overgrowth, Diet and Trimming | E46: Teeth | F46: NEW
A47: 46 | B47: puffer fish size | C47: https://www.fishcareai.com/guides/puffer-fish-care/size-growth/ | D47: How Big Do Puffer Fish Get? Size and Growth Rate | E47: Size & Growth | F47: NEW
A48: 47 | B48: how big do puffer fish get | C48: https://www.fishcareai.com/guides/puffer-fish-care/size-growth/ | D48: How Big Do Puffer Fish Get? Size and Growth Rate | E48: Size & Growth | F48: NEW
A49: 48 | B49: puffer fish growth rate | C49: https://www.fishcareai.com/guides/puffer-fish-care/size-growth/ | D49: How Big Do Puffer Fish Get? Size and Growth Rate | E49: Size & Growth | F49: NEW
A50: 49 | B50: puffer fish lifespan | C50: https://www.fishcareai.com/guides/puffer-fish-care/lifespan/ | D50: Puffer Fish Lifespan: How Long Do Puffer Fish Live? | E50: Lifespan | F50: NEW
... A52: 51 | B52: how long do puffer fish live | C52: https://www.fishcareai.com/guides/puffer-fish-care/lifespan/ | D52: Puffer Fish Lifespan: How Long Do Puffer Fish Live? | E52: Lifespan | F52: NEW
A53: 52 | B53: dwarf puffer fish | C53: https://www.fishcareai.com/guides/puffer-fish-care/pea-puffer/ | D53: Pea Puffer Care: Tank Size, Food, Lifespan and Tank Mates | E53: Species: Pea Puffer | F53: NEW | G53: https://www.fishcareai.com/wiki/pea-puffer/
...

Sheet Pages
A1: # | B1: URL | C1: Page Title | D1: Cluster Section | E1: Page Status | F1: Keyword Count | G1: Target Keywords | H1: Meta Description
A2: 1 | B2: https://www.fishcareai.com/guides/puffer-fish-care/ | C2: Puffer Fish Care Guide: Tank, Water, Food and Species | D2: Pillar | E2: NEW | F2: =COUNTIF('Keyword Map'!$C$2:$C$120,B2) | G2: tetraodontidae · tetraodontidae fish · tetraodontidae pufferfish · puffer fish · pufferfish · puffer fish care · pufferfish care · how to care for puffer fish | H2: Complete puffer fish care guide: tank size, water parameters, feeding, teeth, tank mates and lifespan for pea, figure 8, green spotted, fahaka and mbu puffers.
A3: 2 | B3: https://www.fishcareai.com/guides/puffer-fish-care/types/ | C3: Types of Puffer Fish: 20 Species by Size and Water Type | D3: Types & Species | E3: NEW | F3: =COUNTIF('Keyword Map'!$C$2:$C$120,B3) | G3: types of puffer fish · puffer fish species · pufferfish species · types of freshwater puffer fish · freshwater puffer fish species · small puffer fish · congo puffer · congo puffer fish · congo puffer care · avocado puffer · red eye puffer · hairy puffer fish | H3: Types of puffer fish compared: freshwater, brackish and saltwater species with adult size, tank size and temperament, from pea puffers to the mbu.
A4: 3 | B4: https://www.fishcareai.com/guides/puffer-fish-care/freshwater/ | C4: Freshwater Puffer Fish: Species, Care and Tank Setup | D4: Freshwater | E4: NEW | F4: =COUNTIF('Keyword Map'!$C$2:$C$120,B4) | G4: freshwater puffer fish · freshwater pufferfish · freshwater puffer fish care | H4: Freshwater puffer fish care: the 8 true freshwater species, tank setup by feeding style, water parameters, diet and which shop puffers are actually brackish.
A5: 4 | B5: https://www.fishcareai.com/guides/puffer-fish-care/saltwater/ | C5: Saltwater Puffer Fish Care: Species, Tank Size and Diet | D5: Saltwater | E5: NEW | F5: =COUNTIF('Keyword Map'!$C$2:$C$120,B5) | G5: saltwater puffer fish · saltwater pufferfish · porcupine puffer fish · dogface puffer fish · valentini puffer | H5: Saltwater puffer fish care: porcupine, dogface and valentini puffers compared, marine water parameters, tank size, shell-on feeding and why copper is unsafe.
A6: 5 | B6: https://www.fishcareai.com/guides/puffer-fish-care/tank-size/ | C6: Puffer Fish Tank Size: Minimum Gallons by Species | D6: Tank Size | E6: NEW | F6: =COUNTIF('Keyword Map'!$C$2:$C$120,B6) | G6: puffer fish tank · puffer fish tank size · pufferfish tank size · freshwater puffer fish tank | H6: Puffer fish tank size by species: 10 gallons for a pea puffer trio, 30 for a green spotted puffer, 125 for a fahaka. Filtration, footprint and setup guidance.
A7: 6 | B7: https://www.fishcareai.com/guides/puffer-fish-care/water-parameters/ | C7: Puffer Fish Water Parameters: Temperature, pH and Salinity | D7: Water Parameters | E7: NEW | F7: =COUNTIF('Keyword Map'!$C$2:$C$120,B7) | G7: puffer fish water temperature · puffer fish temperature · puffer fish water parameters · puffer fish pH · freshwater puffer water parameters | H7: Puffer fish water parameters: temperature 75-82F, pH 7.0-8.0, hardness targets and brackish specific gravity charts for figure 8 and green spotted puffers.
A8: 7 | B8: https://www.fishcareai.com/guides/puffer-fish-care/food/ | C8: What Do Puffer Fish Eat? Food and Feeding Guide | D8: Food & Feeding | E8: NEW | F8: =COUNTIF('Keyword Map'!$C$2:$C$120,B8) | G8: puffer fish food · what do puffer fish eat · what to feed puffer fish · best food for puffer fish · puffer fish feeding · how often to feed puffer fish | H8: What to feed puffer fish: snails, clams and shell-on foods that grind their teeth, plus feeding frequency by species, portion sizes and why pellets do not work.
A9: 8 | B9: https://www.fishcareai.com/guides/puffer-fish-care/teeth/ | C9: Puffer Fish Teeth: Overgrowth, Diet and Trimming | D9: Teeth | E9: NEW | F9: =COUNTIF('Keyword Map'!$C$2:$C$120,B9) | G9: puffer fish teeth · puffer fish teeth trimming | H9: Why puffer fish teeth never stop growing, how to prevent overgrowth with snails and shell-on food, warning signs, and how puffer teeth trimming is done safely.
A10: 9 | B10: https://www.fishcareai.com/guides/puffer-fish-care/size-growth/ | C10: How Big Do Puffer Fish Get? Size and Growth Rate | D10: Size & Growth | E10: NEW | F10: =COUNTIF('Keyword Map'!$C$2:$C$120,B10) | G10: puffer fish size · how big do puffer fish get · puffer fish growth rate | H10: Puffer fish size by species, from the 1.4-inch pea puffer to the 30-inch mbu, with growth rates and why a small tank never keeps a puffer small.
A11: 10 | B11: https://www.fishcareai.com/guides/puffer-fish-care/lifespan/ | C11: Puffer Fish Lifespan: How Long Do Puffer Fish Live? | D11: Lifespan | E11: NEW | F11: =COUNTIF('Keyword Map'!$C$2:$C$120,B11) | G11: puffer fish lifespan · pufferfish lifespan · how long do puffer fish live | H11: Puffer fish lifespan by species: 4-5 years for a pea puffer, 10-15 for figure 8 and green spotted puffers, 20+ for an mbu, and what shortens it.
A12: 11 | B12: https://www.fishcareai.com/guides/puffer-fish-care/pea-puffer/ | C12: Pea Puffer Care: Tank Size, Food, Lifespan and Tank Mates | D12: Species: Pea Puffer | E12: NEW | F12: =COUNTIF('Keyword Map'!$C$2:$C$120,B12) | G12: dwarf puffer fish · pea puffer · pea puffer fish · pea puffer care · pea puffer tank size · pea puffer lifespan · pea puffer food · pea puffer water parameters · pea puffer tank mates · dwarf puffer · dwarf puffer care | H12: Pea puffer care guide: 10 gallon tank for a trio, 74-82F freshwater, snail and blackworm diet, sexing males and females, tank mates and a 4-5 year lifespan.
A13: 12 | B13: https://www.fishcareai.com/guides/puffer-fish-care/figure-8-puffer/ | C13: Figure 8 Puffer Care: Tank Size, Brackish Water and Diet | D13: Species: Figure 8 | E13: NEW | F13: =COUNTIF('Keyword Map'!$C$2:$C$120,B13) | G13: figure 8 puffer · figure 8 puffer fish · figure 8 puffer care · figure 8 puffer tank size · figure 8 puffer tank mates | H13: Figure 8 puffer care: 15-20 gallon tank, brackish specific gravity 1.005-1.008, a snail and clam diet, tank mates, and a 10-15 year lifespan.
... A33: 32 | B33: https://www.fishcareai.com/compatibility/goldfish-and-pea-puffer/ | C33: Can Goldfish Live With Pea Puffer? Compatibility Guide | D33: Compatibility pairing | E33: EXISTING | F33: =COUNTIF('Keyword Map'!$C$2:$C$120,B33) | G33: puffer fish and goldfish | H33: ❌ Not Compatible: Goldfish and Pea Puffer compatibility — temperature, pH, aggression risk, tank size, and verdict for keeping them together.
E34: TOTAL | F34: =SUM(F2:F33)

Sheet Notes
A1: Puffer Fish Keyword → URL Map
A3: Site | B3: https://www.fishcareai.com
A4: Cluster | B4: /guides/puffer-fish-care/
A5: Built | B5: 2026-09-09
A6: Generator | B6: data-pipeline/generate_puffer_cluster.py (re-runnable)
A7: Worklog | B7: WORKLOG-2026-09-09-puffer.md
A9: Sheet: Keyword Map | B9: One row per supplied keyword, pointing at the page that targets it.
A10: Sheet: Pages | B10: One row per URL, listing every keyword it targets. Keyword Count is a live COUNTIF.
A12: Page Status: NEW | B12: Page created for this cluster (24 pages under /guides/puffer-fish-care/).
A13: Page Status: EXISTING | B13: Page already existed; it was given inbound links to the new cluster.
A15: Secondary / Supporting URL | B15: A second page on the site that also serves the keyword and is internally linked.
A16: Pairing keywords | B16: Served by /compatibility/*-and-pea-puffer/ pages, which are also linked from /guides/puffer-fish-care/tank-mates/.
A18: Note | B18: 'dwarf puffer fish' appeared twice in the supplied list and is counted once here.
A19: Note | B19: All 24 new URLs are in sitemaps/guides.xml with lastmod 2026-09-09.
